Traceback (most recent call last):
  File "/home/runner/.cache/pypoetry/virtualenvs/mtbp3-STzYEG9e-py3.10/lib/python3.10/site-packages/jupyter_cache/executors/utils.py", line 58, in single_nb_execution
    executenb(
  File "/home/runner/.cache/pypoetry/virtualenvs/mtbp3-STzYEG9e-py3.10/lib/python3.10/site-packages/nbclient/client.py", line 1314, in execute
    return NotebookClient(nb=nb, resources=resources, km=km, **kwargs).execute()
  File "/home/runner/.cache/pypoetry/virtualenvs/mtbp3-STzYEG9e-py3.10/lib/python3.10/site-packages/jupyter_core/utils/__init__.py", line 165, in wrapped
    return loop.run_until_complete(inner)
  File "/opt/hostedtoolcache/Python/3.10.13/x64/lib/python3.10/asyncio/base_events.py", line 649, in run_until_complete
    return future.result()
  File "/home/runner/.cache/pypoetry/virtualenvs/mtbp3-STzYEG9e-py3.10/lib/python3.10/site-packages/nbclient/client.py", line 709, in async_execute
    await self.async_execute_cell(
  File "/home/runner/.cache/pypoetry/virtualenvs/mtbp3-STzYEG9e-py3.10/lib/python3.10/site-packages/nbclient/client.py", line 1062, in async_execute_cell
    await self._check_raise_for_error(cell, cell_index, exec_reply)
  File "/home/runner/.cache/pypoetry/virtualenvs/mtbp3-STzYEG9e-py3.10/lib/python3.10/site-packages/nbclient/client.py", line 918, in _check_raise_for_error
    raise CellExecutionError.from_cell_and_msg(cell, exec_reply_content)
nbclient.exceptions.CellExecutionError: An error occurred while executing the following cell:
------------------
id = emt.find_soc([name.upper() for name in soc_names[:3]], ignore_case=True)
print(id)
------------------


[0;31m---------------------------------------------------------------------------[0m
[0;31mTypeError[0m                                 Traceback (most recent call last)
Cell [0;32mIn[4], line 1[0m
[0;32m----> 1[0m [38;5;28mid[39m [38;5;241m=[39m [43memt[49m[38;5;241;43m.[39;49m[43mfind_soc[49m[43m([49m[43m[[49m[43mname[49m[38;5;241;43m.[39;49m[43mupper[49m[43m([49m[43m)[49m[43m [49m[38;5;28;43;01mfor[39;49;00m[43m [49m[43mname[49m[43m [49m[38;5;129;43;01min[39;49;00m[43m [49m[43msoc_names[49m[43m[[49m[43m:[49m[38;5;241;43m3[39;49m[43m][49m[43m][49m[43m,[49m[43m [49m[43mignore_case[49m[38;5;241;43m=[39;49m[38;5;28;43;01mTrue[39;49;00m[43m)[49m
[1;32m      2[0m [38;5;28mprint[39m([38;5;28mid[39m)

[0;31mTypeError[0m: Emt.find_soc() got an unexpected keyword argument 'ignore_case'

