Traceback (most recent call last):
  File "/home/runner/.cache/pypoetry/virtualenvs/mtbp3-STzYEG9e-py3.10/lib/python3.10/site-packages/jupyter_cache/executors/utils.py", line 58, in single_nb_execution
    executenb(
  File "/home/runner/.cache/pypoetry/virtualenvs/mtbp3-STzYEG9e-py3.10/lib/python3.10/site-packages/nbclient/client.py", line 1314, in execute
    return NotebookClient(nb=nb, resources=resources, km=km, **kwargs).execute()
  File "/home/runner/.cache/pypoetry/virtualenvs/mtbp3-STzYEG9e-py3.10/lib/python3.10/site-packages/jupyter_core/utils/__init__.py", line 165, in wrapped
    return loop.run_until_complete(inner)
  File "/opt/hostedtoolcache/Python/3.10.13/x64/lib/python3.10/asyncio/base_events.py", line 649, in run_until_complete
    return future.result()
  File "/home/runner/.cache/pypoetry/virtualenvs/mtbp3-STzYEG9e-py3.10/lib/python3.10/site-packages/nbclient/client.py", line 709, in async_execute
    await self.async_execute_cell(
  File "/home/runner/.cache/pypoetry/virtualenvs/mtbp3-STzYEG9e-py3.10/lib/python3.10/site-packages/nbclient/client.py", line 1062, in async_execute_cell
    await self._check_raise_for_error(cell, cell_index, exec_reply)
  File "/home/runner/.cache/pypoetry/virtualenvs/mtbp3-STzYEG9e-py3.10/lib/python3.10/site-packages/nbclient/client.py", line 918, in _check_raise_for_error
    raise CellExecutionError.from_cell_and_msg(cell, exec_reply_content)
nbclient.exceptions.CellExecutionError: An error occurred while executing the following cell:
------------------
id = emt.find_soc(soc_names[:3])
print(id)
------------------


[0;31m---------------------------------------------------------------------------[0m
[0;31mAttributeError[0m                            Traceback (most recent call last)
Cell [0;32mIn[3], line 1[0m
[0;32m----> 1[0m [38;5;28mid[39m [38;5;241m=[39m [43memt[49m[38;5;241;43m.[39;49m[43mfind_soc[49m[43m([49m[43msoc_names[49m[43m[[49m[43m:[49m[38;5;241;43m3[39;49m[43m][49m[43m)[49m
[1;32m      2[0m [38;5;28mprint[39m([38;5;28mid[39m)

File [0;32m~/work/mtbp3/mtbp3/mtbp3/util/emt.py:174[0m, in [0;36mEmt.find_soc[0;34m(self, soc_name, ignore_case)[0m
[1;32m    172[0m [38;5;28;01melse[39;00m:
[1;32m    173[0m     soc_name_df [38;5;241m=[39m pd[38;5;241m.[39mDataFrame(soc_name)
[0;32m--> 174[0m     [38;5;28;01mif[39;00m [38;5;28;43mself[39;49m[38;5;241;43m.[39;49m[43mignore_case[49m:
[1;32m    175[0m         out [38;5;241m=[39m pd[38;5;241m.[39mmerge(soc_name_df, subset, left_on[38;5;241m=[39msoc_name_df[[38;5;241m0[39m][38;5;241m.[39mstr[38;5;241m.[39mlower(), right_on[38;5;241m=[39msubset[[38;5;241m7[39m][38;5;241m.[39mstr[38;5;241m.[39mlower(), how[38;5;241m=[39m[38;5;124m'[39m[38;5;124mleft[39m[38;5;124m'[39m, sort[38;5;241m=[39m[38;5;28;01mFalse[39;00m)[[38;5;241m3[39m][38;5;241m.[39mtolist()
[1;32m    176[0m     [38;5;28;01melse[39;00m:

[0;31mAttributeError[0m: 'Emt' object has no attribute 'ignore_case'

