Traceback (most recent call last):
  File "/home/runner/.cache/pypoetry/virtualenvs/mtbp3-STzYEG9e-py3.10/lib/python3.10/site-packages/jupyter_cache/executors/utils.py", line 58, in single_nb_execution
    executenb(
  File "/home/runner/.cache/pypoetry/virtualenvs/mtbp3-STzYEG9e-py3.10/lib/python3.10/site-packages/nbclient/client.py", line 1314, in execute
    return NotebookClient(nb=nb, resources=resources, km=km, **kwargs).execute()
  File "/home/runner/.cache/pypoetry/virtualenvs/mtbp3-STzYEG9e-py3.10/lib/python3.10/site-packages/jupyter_core/utils/__init__.py", line 165, in wrapped
    return loop.run_until_complete(inner)
  File "/opt/hostedtoolcache/Python/3.10.14/x64/lib/python3.10/asyncio/base_events.py", line 649, in run_until_complete
    return future.result()
  File "/home/runner/.cache/pypoetry/virtualenvs/mtbp3-STzYEG9e-py3.10/lib/python3.10/site-packages/nbclient/client.py", line 709, in async_execute
    await self.async_execute_cell(
  File "/home/runner/.cache/pypoetry/virtualenvs/mtbp3-STzYEG9e-py3.10/lib/python3.10/site-packages/nbclient/client.py", line 1062, in async_execute_cell
    await self._check_raise_for_error(cell, cell_index, exec_reply)
  File "/home/runner/.cache/pypoetry/virtualenvs/mtbp3-STzYEG9e-py3.10/lib/python3.10/site-packages/nbclient/client.py", line 918, in _check_raise_for_error
    raise CellExecutionError.from_cell_and_msg(cell, exec_reply_content)
nbclient.exceptions.CellExecutionError: An error occurred while executing the following cell:
------------------
print( summary.count_to_cate(['study', 'treatment', 'visit'], 'N(all)', [0,3,5,7], stats=['count','total_count']) )

------------------


[0;31m---------------------------------------------------------------------------[0m
[0;31mValueError[0m                                Traceback (most recent call last)
Cell [0;32mIn[3], line 1[0m
[0;32m----> 1[0m [38;5;28mprint[39m( [43msummary[49m[38;5;241;43m.[39;49m[43mcount_to_cate[49m[43m([49m[43m[[49m[38;5;124;43m'[39;49m[38;5;124;43mstudy[39;49m[38;5;124;43m'[39;49m[43m,[49m[43m [49m[38;5;124;43m'[39;49m[38;5;124;43mtreatment[39;49m[38;5;124;43m'[39;49m[43m,[49m[43m [49m[38;5;124;43m'[39;49m[38;5;124;43mvisit[39;49m[38;5;124;43m'[39;49m[43m][49m[43m,[49m[43m [49m[38;5;124;43m'[39;49m[38;5;124;43mN(all)[39;49m[38;5;124;43m'[39;49m[43m,[49m[43m [49m[43m[[49m[38;5;241;43m0[39;49m[43m,[49m[38;5;241;43m3[39;49m[43m,[49m[38;5;241;43m5[39;49m[43m,[49m[38;5;241;43m7[39;49m[43m][49m[43m,[49m[43m [49m[43mstats[49m[38;5;241;43m=[39;49m[43m[[49m[38;5;124;43m'[39;49m[38;5;124;43mcount[39;49m[38;5;124;43m'[39;49m[43m,[49m[38;5;124;43m'[39;49m[38;5;124;43mtotal_count[39;49m[38;5;124;43m'[39;49m[43m][49m[43m)[49m )

File [0;32m~/work/mtbp3/mtbp3/mtbp3/health/clinical.py:82[0m, in [0;36msummary_by_group.count_to_cate[0;34m(self, group_columns, target_column, bins, stats)[0m
[1;32m     80[0m     [38;5;28;01mraise[39;00m [38;5;167;01mValueError[39;00m([38;5;124m"[39m[38;5;124mtarget_column should be a non-empty string.[39m[38;5;124m"[39m)
[1;32m     81[0m [38;5;28;01mif[39;00m target_column [38;5;129;01mnot[39;00m [38;5;129;01min[39;00m [38;5;28mself[39m[38;5;241m.[39mdf[38;5;241m.[39mcolumns:
[0;32m---> 82[0m     [38;5;28;01mraise[39;00m [38;5;167;01mValueError[39;00m([38;5;124mf[39m[38;5;124m"[39m[38;5;124mColumn [39m[38;5;124m'[39m[38;5;132;01m{[39;00mtarget_column[38;5;132;01m}[39;00m[38;5;124m'[39m[38;5;124m does not exist in the DataFrame.[39m[38;5;124m"[39m)
[1;32m     83[0m [38;5;28;01mif[39;00m [38;5;129;01mnot[39;00m pd[38;5;241m.[39mapi[38;5;241m.[39mtypes[38;5;241m.[39mis_numeric_dtype([38;5;28mself[39m[38;5;241m.[39mdf[target_column]):
[1;32m     84[0m     [38;5;28;01mraise[39;00m [38;5;167;01mValueError[39;00m([38;5;124mf[39m[38;5;124m"[39m[38;5;124mColumn [39m[38;5;124m'[39m[38;5;132;01m{[39;00mtarget_column[38;5;132;01m}[39;00m[38;5;124m'[39m[38;5;124m is not a numerical column.[39m[38;5;124m"[39m)

[0;31mValueError[0m: Column 'N(all)' does not exist in the DataFrame.

