Traceback (most recent call last):
  File "/home/runner/.cache/pypoetry/virtualenvs/mtbp3-STzYEG9e-py3.10/lib/python3.10/site-packages/jupyter_cache/executors/utils.py", line 58, in single_nb_execution
    executenb(
  File "/home/runner/.cache/pypoetry/virtualenvs/mtbp3-STzYEG9e-py3.10/lib/python3.10/site-packages/nbclient/client.py", line 1314, in execute
    return NotebookClient(nb=nb, resources=resources, km=km, **kwargs).execute()
  File "/home/runner/.cache/pypoetry/virtualenvs/mtbp3-STzYEG9e-py3.10/lib/python3.10/site-packages/jupyter_core/utils/__init__.py", line 165, in wrapped
    return loop.run_until_complete(inner)
  File "/opt/hostedtoolcache/Python/3.10.14/x64/lib/python3.10/asyncio/base_events.py", line 649, in run_until_complete
    return future.result()
  File "/home/runner/.cache/pypoetry/virtualenvs/mtbp3-STzYEG9e-py3.10/lib/python3.10/site-packages/nbclient/client.py", line 709, in async_execute
    await self.async_execute_cell(
  File "/home/runner/.cache/pypoetry/virtualenvs/mtbp3-STzYEG9e-py3.10/lib/python3.10/site-packages/nbclient/client.py", line 1062, in async_execute_cell
    await self._check_raise_for_error(cell, cell_index, exec_reply)
  File "/home/runner/.cache/pypoetry/virtualenvs/mtbp3-STzYEG9e-py3.10/lib/python3.10/site-packages/nbclient/client.py", line 918, in _check_raise_for_error
    raise CellExecutionError.from_cell_and_msg(cell, exec_reply_content)
nbclient.exceptions.CellExecutionError: An error occurred while executing the following cell:
------------------

print("Cohen's kappa:", cohen_kappa_score(r1, r2))
------------------


[0;31m---------------------------------------------------------------------------[0m
[0;31mNameError[0m                                 Traceback (most recent call last)
Cell [0;32mIn[2], line 1[0m
[0;32m----> 1[0m [38;5;28mprint[39m([38;5;124m"[39m[38;5;124mCohen[39m[38;5;124m'[39m[38;5;124ms kappa:[39m[38;5;124m"[39m, cohen_kappa_score([43mr1[49m, r2))

[0;31mNameError[0m: name 'r1' is not defined

