Traceback (most recent call last):
  File "/home/runner/.cache/pypoetry/virtualenvs/mtbp3-STzYEG9e-py3.10/lib/python3.10/site-packages/jupyter_cache/executors/utils.py", line 58, in single_nb_execution
    executenb(
  File "/home/runner/.cache/pypoetry/virtualenvs/mtbp3-STzYEG9e-py3.10/lib/python3.10/site-packages/nbclient/client.py", line 1314, in execute
    return NotebookClient(nb=nb, resources=resources, km=km, **kwargs).execute()
  File "/home/runner/.cache/pypoetry/virtualenvs/mtbp3-STzYEG9e-py3.10/lib/python3.10/site-packages/jupyter_core/utils/__init__.py", line 165, in wrapped
    return loop.run_until_complete(inner)
  File "/opt/hostedtoolcache/Python/3.10.14/x64/lib/python3.10/asyncio/base_events.py", line 649, in run_until_complete
    return future.result()
  File "/home/runner/.cache/pypoetry/virtualenvs/mtbp3-STzYEG9e-py3.10/lib/python3.10/site-packages/nbclient/client.py", line 709, in async_execute
    await self.async_execute_cell(
  File "/home/runner/.cache/pypoetry/virtualenvs/mtbp3-STzYEG9e-py3.10/lib/python3.10/site-packages/nbclient/client.py", line 1062, in async_execute_cell
    await self._check_raise_for_error(cell, cell_index, exec_reply)
  File "/home/runner/.cache/pypoetry/virtualenvs/mtbp3-STzYEG9e-py3.10/lib/python3.10/site-packages/nbclient/client.py", line 918, in _check_raise_for_error
    raise CellExecutionError.from_cell_and_msg(cell, exec_reply_content)
nbclient.exceptions.CellExecutionError: An error occurred while executing the following cell:
------------------
from IPython.display import Image 

img.resize(width=300)
display(img)
------------------


[0;31m---------------------------------------------------------------------------[0m
[0;31mTypeError[0m                                 Traceback (most recent call last)
Cell [0;32mIn[4], line 3[0m
[1;32m      1[0m [38;5;28;01mfrom[39;00m [38;5;21;01mIPython[39;00m[38;5;21;01m.[39;00m[38;5;21;01mdisplay[39;00m [38;5;28;01mimport[39;00m Image 
[0;32m----> 3[0m [43mimg[49m[38;5;241;43m.[39;49m[43mresize[49m[43m([49m[43mwidth[49m[38;5;241;43m=[39;49m[38;5;241;43m300[39;49m[43m)[49m
[1;32m      4[0m display(img)

[0;31mTypeError[0m: Image.resize() got an unexpected keyword argument 'width'

